Workbook

Sheet 1. Summary
A1: 1. Daily Group Cash Position Report -
A2: Purpose: Immediate visibility of available liquidity
A4: Entity | B4: Bank | C4: Account type | D4: Account # | E4: Currency | F4: Opening Balance | G4: Inflows | H4: Outflows | I4: Closing Balance | J4: Restricted Cash | K4: Available Cash | M4: ='1 & 3 GSIB'!L4 -> USD closing Balance
A5: ='1 & 3 GSIB'!A5 -> George Steuart Insurance Brokers (Pvt) Ltd | B5: ='1 & 3 GSIB'!B5 -> Cargills | C5: ='1 & 3 GSIB'!C5 -> Current | D5: ='1 & 3 GSIB'!D5 -> 1950000702 | E5: ='1 & 3 GSIB'!E5 -> LKR
B6: ='1 & 3 GSIB'!B6 -> Cargills | C6: ='1 & 3 GSIB'!C6 -> Higher Saving | D6: ='1 & 3 GSIB'!D6 -> 0011 0700 6091 | E6: ='1 & 3 GSIB'!E6 -> LKR
B7: ='1 & 3 GSIB'!B7 -> Cargills | C7: ='1 & 3 GSIB'!C7 -> Saving | D7: ='1 & 3 GSIB'!D7 -> 1103000201 | E7: ='1 & 3 GSIB'!E7 -> LKR
B8: ='1 & 3 GSIB'!B8 -> Cargills | C8: ='1 & 3 GSIB'!C8 -> Saving | D8: ='1 & 3 GSIB'!D8 -> 0011 0700 9604 | E8: ='1 & 3 GSIB'!E8 -> LKR
B9: ='1 & 3 GSIB'!B9 -> NDB | C9: ='1 & 3 GSIB'!C9 -> Saving | D9: ='1 & 3 GSIB'!D9 -> 106590006893 | E9: ='1 & 3 GSIB'!E9 -> USD
B10: ='1 & 3 GSIB'!B10 -> NDB | C10: ='1 & 3 GSIB'!C10 -> Current | D10: ='1 & 3 GSIB'!D10 -> 101001103866 | E10: ='1 & 3 GSIB'!E10 -> LKR
B11: ='1 & 3 GSIB'!B11 -> BOC | C11: ='1 & 3 GSIB'!C11 -> Saving | D11: ='1 & 3 GSIB'!D11 -> 91834522 | E11: ='1 & 3 GSIB'!E11 -> LKR
B12: ='1 & 3 GSIB'!B12 -> BOC | C12: ='1 & 3 GSIB'!C12 -> Current | D12: ='1 & 3 GSIB'!D12 -> 91834503 | E12: ='1 & 3 GSIB'!E12 -> LKR
B13: ='1 & 3 GSIB'!B13 -> Sampath | C13: ='1 & 3 GSIB'!C13 -> Saving | D13: ='1 & 3 GSIB'!D13 -> 5034 2000 3627 | E13: ='1 & 3 GSIB'!E13 -> USD
B14: ='1 & 3 GSIB'!B14 -> Sampath | C14: ='1 & 3 GSIB'!C14 -> Current | D14: ='1 & 3 GSIB'!D14 -> 0034 1001 2218 | E14: ='1 & 3 GSIB'!E14 -> LKR
B15: ='1 & 3 GSIB'!B15 -> Seylan | C15: ='1 & 3 GSIB'!C15 -> Current | D15: ='1 & 3 GSIB'!D15 -> 0860 12728996 001 | E15: ='1 & 3 GSIB'!E15 -> LKR
B16: ='1 & 3 GSIB'!B16 -> Seylan | C16: ='1 & 3 GSIB'!C16 -> Current | D16: ='1 & 3 GSIB'!D16 -> 0860 12728996 002 | E16: ='1 & 3 GSIB'!E16 -> LKR
B17: ='1 & 3 GSIB'!B17 -> Seylan | C17: ='1 & 3 GSIB'!C17 -> Saving | D17: ='1 & 3 GSIB'!D17 -> 0860 12728996 066 | E17: ='1 & 3 GSIB'!E17 -> USD
... B22: ='1 & 3 GSIB'!B22 -> Commercial | C22: ='1 & 3 GSIB'!C22 -> Current | D22: ='1 & 3 GSIB'!D22 -> (1)-1020012908 | E22: ='1 & 3 GSIB'!E22 -> LKR
A23: George Steuart Health (Pvt) Ltd | B23: ='1. GSH'!B5 -> NDB | C23: ='1. GSH'!C5 -> Current | D23: ='1. GSH'!D5 -> 1010 0002 5071 | E23: ='1. GSH'!E5 -> LKR
B24: ='1. GSH'!B6 -> NDB | C24: ='1. GSH'!C6 -> Saving | D24: ='1. GSH'!D6 -> 1065-9000-6001 | E24: ='1. GSH'!E6 -> USD
B25: ='1. GSH'!B7 -> DFCC | C25: ='1. GSH'!C7 -> Current | D25: ='1. GSH'!D7 -> 102072013996 | E25: ='1. GSH'!E7 -> USD
B26: ='1. GSH'!B8 -> DFCC | C26: ='1. GSH'!C8 -> Current | D26: ='1. GSH'!D8 -> 101014573128 | E26: ='1. GSH'!E8 -> LKR
B27: ='1. GSH'!B9 -> Seylan | C27: ='1. GSH'!C9 -> Current | D27: ='1. GSH'!D9 -> 0080-13334985-001 | E27: ='1. GSH'!E9 -> LKR
B28: ='1. GSH'!B10 -> Seylan | C28: ='1. GSH'!C10 -> Current | D28: ='1. GSH'!D10 -> 0860-13334985002 | E28: ='1. GSH'!E10 -> LKR
B29: ='1. GSH'!B11 -> Sampath | C29: ='1. GSH'!C11 -> Current | D29: ='1. GSH'!D11 -> 0091-1000-7245 | E29: ='1. GSH'!E11 -> LKR
B30: ='1. GSH'!B12 -> Sampath | C30: ='1. GSH'!C12 -> Current | D30: ='1. GSH'!D12 -> 0009- 3000 -0027 | E30: ='1. GSH'!E12 -> LKR
B31: ='1. GSH'!B13 -> Sampath | C31: ='1. GSH'!C13 -> Current | D31: ='1. GSH'!D13 -> 0018 1000 4351 | E31: ='1. GSH'!E13 -> LKR
B32: ='1. GSH'!B14 -> HNB | C32: ='1. GSH'!C14 -> Current | D32: ='1. GSH'!D14 -> 61010277822 | E32: ='1. GSH'!E14 -> LKR
B33: ='1. GSH'!B15 -> HNB | C33: ='1. GSH'!C15 -> Current | D33: ='1. GSH'!D15 -> 0020 1000 3748 | E33: ='1. GSH'!E15 -> LKR
B34: ='1. GSH'!B16 -> Peoples | C34: ='1. GSH'!C16 -> Current | D34: ='1. GSH'!D16 -> 4100191976807 | E34: ='1. GSH'!E16 -> LKR
B35: ='1. GSH'!B17 -> BOC | C35: ='1. GSH'!C17 -> Current | D35: ='1. GSH'!D17 -> 70848912 | E35: ='1. GSH'!E17 -> LKR
... B37: ='1. GSH'!B19 -> Comm Bank | C37: ='1. GSH'!C19 -> MMS | D37: ='1. GSH'!D19 -> 1020012905 | E37: ='1. GSH'!E19 -> LKR
A38: George Steuart Teas (Pvt) Ltd | B38: ='1 & 3 GST'!B7 -> BOC | C38: ='1 & 3 GST'!C7 -> C/A | D38: ='1 & 3 GST'!D7 -> 7230989 | E38: ='1 & 3 GST'!E7 -> LKR
B39: ='1 & 3 GST'!B8 -> BOC | C39: ='1 & 3 GST'!C8 -> BFCA | D39: ='1 & 3 GST'!D8 -> 7231039 | E39: ='1 & 3 GST'!E8 -> USD
B40: ='1 & 3 GST'!B9 -> BOC | C40: ='1 & 3 GST'!C9 -> BLA | D40: ='1 & 3 GST'!D9 -> 88359063 | E40: ='1 & 3 GST'!E9 -> USD
B41: ='1 & 3 GST'!B10 -> BOC | C41: ='1 & 3 GST'!C10 -> BFCA | D41: ='1 & 3 GST'!D10 -> 71799300 | E41: ='1 & 3 GST'!E10 -> EURO
B42: ='1 & 3 GST'!B11 -> Peoples | C42: ='1 & 3 GST'!C11 -> C/A | D42: ='1 & 3 GST'!D11 -> 148100130046167 | E42: ='1 & 3 GST'!E11 -> LKR
B43: ='1 & 3 GST'!B12 -> Peoples | C43: ='1 & 3 GST'!C12 -> BFCA | D43: ='1 & 3 GST'!D12 -> 148402130046167 | E43: ='1 & 3 GST'!E12 -> USD
B44: ='1 & 3 GST'!B15 -> Seylan | C44: ='1 & 3 GST'!C15 -> C/A | D44: ='1 & 3 GST'!D15 -> 86013585844001 | E44: ='1 & 3 GST'!E15 -> LKR
B45: ='1 & 3 GST'!B16 -> Seylan | C45: ='1 & 3 GST'!C16 -> BFCA | D45: ='1 & 3 GST'!D16 -> 86013585844050 | E45: ='1 & 3 GST'!E16 -> USD
B46: ='1 & 3 GST'!B17 -> Seylan | C46: ='1 & 3 GST'!C17 -> BLA | D46: ='1 & 3 GST'!D17 -> 86013585844001 | E46: ='1 & 3 GST'!E17 -> USD
...

Sheet 3. Loans
A2: 3. GS Group loan _ deposit portfolio
A4: 3.1 Long Term Loan
A5: Company | B5: Bank | C5: Loan type | D5: Tenor | E5: Facility amount | F5: Initially granted / Restructured date | G5: Current Interest rate | H5: Remaining Tenor | I5: Outstanding amount as at 30 April 2026
A6: George Steuart Health (Pvt) Ltd | B6: ='3. GSH'!B6 -> BOC | C6: ='3. GSH'!C6 -> Capex funding | D6: ='3. GSH'!D6 -> 48 Months
B7: ='3. GSH'!B7 -> Seylan | C7: ='3. GSH'!C7 -> Vehicle | D7: ='3. GSH'!D7 -> 36 Months
B8: ='3. GSH'!B8 -> Seylan | C8: ='3. GSH'!C8 -> Capex funding | D8: ='3. GSH'!D8 -> 84 months - 06 months
B9: ='3. GSH'!B9 -> Seylan | C9: ='3. GSH'!C9 -> Capex funding | D9: ='3. GSH'!D9 -> 84 Months with 03 months Grace Period
A10: George Steuart Teas (Pvt) Ltd | B10: ='1 & 3 GST'!B46 -> BOC | C10: ='1 & 3 GST'!C46 -> Term Loan | D10: 10 Years
B11: ='1 & 3 GST'!B47 -> BOC | C11: ='1 & 3 GST'!C47 -> Term Loan | D11: 10 Years
B12: ='1 & 3 GST'!B48 -> HNB | C12: ='1 & 3 GST'!C48 -> Term Loan | D12: 5 Years
B13: ='1 & 3 GST'!B49 -> HNB | C13: ='1 & 3 GST'!C49 -> Term Loan | D13: 5 Years
B14: ='1 & 3 GST'!B50 -> HNB | C14: ='1 & 3 GST'!C50 -> Term Loan | D14: 5 Years
B15: ='1 & 3 GST'!B51 -> HNB | C15: ='1 & 3 GST'!C51 -> Term Loan | D15: 5 Years
B16: ='1 & 3 GST'!B52 -> PB | C16: ='1 & 3 GST'!C52 -> Term Loan | D16: 3 Years
B17: ='1 & 3 GST'!B53 -> PB | C17: ='1 & 3 GST'!C53 -> Term Loan | D17: 5 Years
A18: George Steuart Travels Ltd | B18: ='1 & 3 GS Ticketing'!B32 -> NDB | C18: ='1 & 3 GS Ticketing'!C32 -> Moratorium Loan | D18: ='1 & 3 GS Ticketing'!D32 -> 5 Years
B19: ='1 & 3 GS Ticketing'!B33 -> Union | C19: ='1 & 3 GS Ticketing'!C33 -> Vehicle Loan | D19: ='1 & 3 GS Ticketing'!D33 -> 5 Years
A20: George Steuart Solutions (Pvt) Ltd | B20: ='2. GSS'!B8 -> GS Travel | C20: ='2. GSS'!C8 -> Intercompany | D20: ='2. GSS'!D8 -> 0
A21: Waskaduwa Beach Resort PLC | B21: Sampath | C21: ='3. Citrus Group'!C8 -> Term Loan | D21: ='3. Citrus Group'!D8 -> 96 Months
C22: ='3. Citrus Group'!C9 -> Term Loan | D22: ='3. Citrus Group'!D9 -> 96 Months
C23: ='3. Citrus Group'!C10 -> Moratorium Loan | D23: ='3. Citrus Group'!D10 -> 40 Months
C24: ='3. Citrus Group'!C11 -> Term Loan | D24: ='3. Citrus Group'!D11 -> 94 Months
C25: ='3. Citrus Group'!C12 -> Term Loan | D25: ='3. Citrus Group'!D12 -> 96 Months
A26: Hikkaduwa Beach Resort PLC | B26: Sampath | C26: ='3. Citrus Group'!C14 -> Term Loan | D26: ='3. Citrus Group'!D14 -> 95 Months
C27: ='3. Citrus Group'!C15 -> Term Loan | D27: ='3. Citrus Group'!D15 -> 95 Months
C28: ='3. Citrus Group'!C16 -> Moratorium Loan | D28: ='3. Citrus Group'!D16 -> 35 Months
C29: ='3. Citrus Group'!C17 -> Term Loan | D29: ='3. Citrus Group'!D17 -> 94 Months
B30: PABC | C30: ='3. Citrus Group'!C18 -> Short Term Loan | D30: ='3. Citrus Group'!D18 -> 60 Months
C31: ='3. Citrus Group'!C19 -> Short Term Loan | D31: ='3. Citrus Group'!D19 -> 60 Months
A32: Citrus Silver Limited | B32: HNB | C32: ='3. Citrus Group'!C21 -> Term Loan | D32: ='3. Citrus Group'!D21 -> 37 Months
C33: ='3. Citrus Group'!C22 -> Short Term Revolving Loan | D33: ='3. Citrus Group'!D22 -> 4 Months
A39: 3.2 Working Capital loan | H39: Syetm alert | J39: Formula
A40: Company | B40: Bank | C40: Facility type | D40: Tenor | E40: Facility amount Rs./FCY | F40: Obtained date | G40: Settlement date | H40: Settlement days passed and overdue | I40: No of days extended | J40: Revised settlement dates | K40: Rate | L40: Outstanding amount as at 30 April 2026 Rs./FCY
A41: George Steuart Health (Pvt) Ltd | B41: ='3. GSH'!B14 -> HNB | C41: ='3. GSH'!C14 -> Money Market Loan | D41: ='3. GSH'!D14 -> 3 Months Revolving
B42: ='3. GSH'!B15 -> HNB | C42: ='3. GSH'!C15 -> Money Market Loan | D42: ='3. GSH'!D15 -> 3 Months Revolving
A43: George Steuart Teas (Pvt) Ltd | B43: ='1 & 3 GST'!B59 -> HNB | C43: ='1 & 3 GST'!C59 -> PCL USD | D43: ='1 & 3 GST'!D59 -> 90 D
B44: ='1 & 3 GST'!B60 -> HNB | C44: ='1 & 3 GST'!C60 -> PCL USD | D44: ='1 & 3 GST'!D60 -> 90 D
B45: ='1 & 3 GST'!B61 -> HNB | C45: ='1 & 3 GST'!C61 -> PCL USD | D45: ='1 & 3 GST'!D61 -> 90 D
B46: ='1 & 3 GST'!B62 -> BOC | C46: ='1 & 3 GST'!C62 -> PCL USD | D46: ='1 & 3 GST'!D62 -> 90 D
B47: ='1 & 3 GST'!B63 -> BOC | C47: ='1 & 3 GST'!C63 -> PCL USD | D47: ='1 & 3 GST'!D63 -> 90 D
...

Sheet 3.3 deposits
A1: 3.3 Fixed Deposit/Other Deposits
E2: Formula | H2: System alert
A3: Company | B3: Bank/Institute | C3: Amount Rs./FCY | D3: Commencement date | E3: Maturity date | F3: Tenor | G3: Rate | H3: Renewal instructions | I3: Pledged details (if any)
A4: ='1 & 3 GSIB'!A47 -> George Steuart Insurance Brokers (Pvt) Ltd | B4: ='1 & 3 GSIB'!B47 -> NDB Wealth
B5: Cargills
B6: Cargills
B7: Cargills
B8: Cargills
B9: Seylan
B10: Seylan
A11: George Steuart Health (Pvt) Ltd | B11: ='3. GSH'!B20 -> NDB
B12: ='3. GSH'!B21 -> NDB
B13: ='3. GSH'!B22 -> NDB
B14: ='3. GSH'!B23 -> NDB
B15: ='3. GSH'!B24 -> DFCC
B16: ='3. GSH'!B25 -> DFCC
B17: ='3. GSH'!B26 -> DFCC
B18: ='3. GSH'!B27 -> DFCC
B19: ='3. GSH'!B28 -> HNB
B20: ='3. GSH'!B29 -> HNB
B21: ='3. GSH'!B30 -> HNB
B22: ='3. GSH'!B31 -> HNB
B23: ='3. GSH'!B32 -> BOC
B24: ='3. GSH'!B33 -> NDB Wealth
A25: George Steuart Teas (Pvt) Ltd | B25: ='1 & 3 GST'!B107 -> HNB
B26: ='1 & 3 GST'!B108 -> HNB
B27: ='1 & 3 GST'!B109 -> HNB
A28: George Steuart Travels Ltd | B28: ='1 & 3 GS Ticketing'!B46 -> NDB
B29: ='1 & 3 GS Ticketing'!B47 -> NDB
B30: ='1 & 3 GS Ticketing'!B48 -> NDB
B31: ='1 & 3 GS Ticketing'!B49 -> NDB
B32: ='1 & 3 GS Ticketing'!B50 -> NDB - Big Saver
B33: ='1 & 3 GS Ticketing'!B51 -> SB - CD
B34: ='1 & 3 GS Ticketing'!B52 -> Cargills
B35: ='1 & 3 GS Ticketing'!B53 -> Cargills
B36: ='1 & 3 GS Ticketing'!B54 -> Cargills
A37: Citrus Silver Limited | B37: Sampath
A39: ='3. Citrus Group'!A34 -> Citrus Leisure PLC | B39: ='3. Citrus Group'!B34 -> Sampath

Sheet 1. GSS
A1: 1. Daily Group Cash Position Report -
A2: Purpose: Immediate visibility of available liquidity
A4: Entity | B4: Bank | C4: Account type | D4: Account # | E4: Currency | F4: Opening Balance - Mar | G4: Inflows | H4: Outflows | I4: Closing Balance | J4: Restricted Cash | K4: Available Cash - 30/04/2026 | L4: Remaks
A6: GSS | B6: Commercial Bank | C6: Current | D6: 1020023631 | E6: LKR | F6: 882056.75 | G6: 9350000 | H6: =8313012.38+615161.57 -> 8928173.9 | I6: =F6+G6-H6 -> 1303882.8 | J6: 0 | K6: =I6 -> 1303882.8
A7: GSS | B7: Commercial Bank | C7: Current | D7: 1000161074 | E7: LKR | F7: 5575441.7 | G7: 19098156 | H7: =16495173.02+203440.96 -> 16698614 | I7: =F7+G7-H7 -> 7974983.5 | J7: 0 | K7: =I7 -> 7974983.5
A8: GSS | B8: Commercial Bank | C8: Current | D8: 1000961599 | E8: LKR | F8: 100000 | G8: 0 | H8: 0 | I8: =F8+G8-H8 -> 100000 | J8: 0 | K8: =I8 -> 100000
A9: GSS | B9: NDB | C9: Current | D9: 101001033396 | E9: LKR | F9: 16997896 | G9: 75425837 | H9: 92427683 | I9: =F9+G9-H9 -> -3950.35 | J9: 0 | K9: 0
A10: GSS | B10: NDB | C10: Saving | D10: 115510157755 | E10: LKR | F10: 3919244.6 | G10: 117454.18 | H10: 0 | I10: =F10+G10-H10 -> 4036698.8 | J10: =I10 -> 4036698.8 | K10: 0 | L10: Cash buildup
A11: GSS | B11: NDB | C11: Saving | D11: 106590006311 | E11: USD | F11: 0.39 | G11: 0 | H11: 0 | I11: =F11+G11-H11 -> 0.39 | K11: =I11 -> 0.39
A12: GSS | B12: NTB | C12: Current | D12: 100020003275 | E12: LKR | F12: 2526090.8 | G12: 19530631 | H12: 40921457 | I12: =F12+G12-H12 -> -18864735 | J12: 0 | K12: 0
A13: GSS | B13: NTB | C13: Saving | D13: 200020042138 | E13: LKR | F13: 48710.41 | G13: 0 | H13: 100 | I13: =F13+G13-H13 -> 48610.41 | J13: 0 | K13: =I13 -> 48610.41
A14: GSS | B14: NTB | C14: Saving | D14: 200020036250 | E14: LKR | F14: 33447161 | G14: 368401.67 | H14: 0 | I14: =F14+G14-H14 -> 33815563 | J14: =I14 -> 33815563 | K14: 0 | L14: Cash buildup
A15: GSS | B15: BOC | C15: Current | D15: 88234820 | E15: LKR | F15: 243017.26 | G15: 0 | H15: =35208.36+2050-6320.88 -> 30937.48 | I15: =F15+G15-H15 -> 212079.78 | J15: 0 | K15: =I15 -> 212079.78
A16: GSS | B16: BOC | C16: Current | D16: 88234806 | E16: LKR | F16: 238594.69 | G16: 0 | H16: 22562.05 | I16: =F16+G16-H16 -> 216032.64 | K16: =I16 -> 216032.64
A17: GSS | B17: Union Bank | C17: Current | D17: 120101000003065 | E17: LKR | F17: -0.24 | G17: 0 | H17: 0 | I17: =F17+G17-H17 -> -0.24 | J17: 0 | K17: =I17 -> -0.24 | L17: Account Closed
A18: GSS | B18: Seylan | C18: Current | D18: 0860-13457848-001 | E18: LKR | F18: 98800 | G18: 0 | H18: 0 | I18: =F18+G18-H18 -> 98800 | J18: 0 | K18: =I18 -> 98800 | L18: Not operate
A19: GSS | B19: Pan Asia | C19: Current | D19: 100111000525 | E19: LKR | F19: 132302 | G19: 0 | H19: 0 | I19: =F19+G19-H19 -> 132302 | J19: 0 | K19: =I19 -> 132302 | L19: Not operate

Sheet 2. GSS
A2: 3. GS Group loan _ deposit portfolio
A4: 3.1 Long Term Loan
A5: Company | B5: Bank | C5: Loan type | D5: Tenor | E5: Facility amount | F5: Initially granted date | G5: Current Interest rate | H5: Remaining Tenor | I5: Settement Date
A7: GSS | B7: GS&C | C7: Intercompany | E7: 0 | G7: 0 | I7: 46112
A8: GSS | B8: GS Travel | C8: Intercompany | E8: 15000000 | G8: 0.1075
A11: 3.2 Working Capital loan
A12: Company | B12: Bank | C12: Facility type | D12: Tenor | E12: Facility amount Rs./FCY | F12: Rate | G12: Outstanding amount as at 07th May 2026 Rs.
A14: GSS | B14: NTB | C14: IML | D14: 150 | E14: 5413947 | F14: 0.0987 | G14: 5413947
A15: GSS | B15: NTB | C15: IML | D15: 150 | E15: 9052095 | F15: 0.0987 | G15: 9052095
A16: GSS | B16: NTB | C16: IML | D16: 150 | E16: 135033.92 | F16: 0.1037 | G16: 135033.92
A17: GSS | B17: NTB | C17: IML | D17: 150 | E17: 107208.75 | F17: 0.1037 | G17: 107208.75
A18: GSS | B18: NTB | C18: IML | D18: 150 | E18: 9904963.1 | F18: 0.1037 | G18: 9904963.1
A19: GSS | B19: NTB | C19: IML | D19: 150 | E19: 1341770 | F19: 0.1037 | G19: 1341770
A20: GSS | B20: NTB | C20: IML | D20: 150 | E20: 92839 | F20: 0.1037 | G20: 92839
A21: GSS | B21: NTB | C21: IML | D21: 150 | E21: 3905304 | F21: 0.1037 | G21: 3905304
A22: GSS | B22: NTB | C22: IML | D22: 150 | E22: 91555 | F22: 0.1037 | G22: 91555
A24: GSS | B24: NDB | C24: IML | D24: 270 | E24: 249913 | F24: 0.0982 | G24: 249913
A25: GSS | B25: NDB | C25: IML | D25: 270 | E25: 4904099 | F25: 0.0982 | G25: 4904099
A26: GSS | B26: NDB | C26: IML | D26: 270 | E26: 12438800 | F26: 0.0982 | G26: 12438800
... A130: GSS | B130: NDB | C130: STL | D130: 270 | E130: 229510 | F130: 0.1154 | G130: 229510
G132: =SUM(G14:G131) -> 2.2851556e+08
A134: 3.3 Fixed Deposit/Other Deposits
A135: Company | B135: Bank/Institute | C135: Amount Rs./FCY | D135: Commencement date | E135: Maturity date | F135: Tenor | G135: Rate | H135: Pledged details (if any)
A137: N/A

Sheet 1. Citrus Group
A1: 1. Daily Group Cash Position Report -
A2: Purpose: Immediate visibility of available liquidity
A4: Entity | B4: Bank | C4: Account type | D4: Account # | E4: Currency | F4: Opening Balance - April 2026 | G4: Inflows | H4: Outflows | I4: Closing Balance | J4: Restricted Cash | K4: Available Cash - April 2026 | L4: * FC Rates from CBSL
A5: Citrus Leisure PLC | B5: NDB Wealth | C5: Money Market A/C | D5: 1048445-01 | E5: LKR | F5: 121597.29 | G5: 760.85 | H5: 0 | I5: 122358.14 | J5: 0 | K5: =+I5 -> 122358.14
A6: Citrus Leisure PLC | B6: PABC | C6: Current | D6: 1001 1100 2815 | E6: LKR | F6: 69791.45 | G6: 0 | H6: -250 | I6: 69541.45 | J6: =+I6 -> 69541.45 | K6: 0
A7: Citrus Leisure PLC | B7: PABC | C7: Current | D7: 1001 1100 0088 | E7: LKR | F7: 25998.48 | G7: 0 | H7: -250 | I7: 25748.48 | J7: =+I7 -> 25748.48 | K7: 0
A8: Citrus Leisure PLC | B8: Sampath | C8: Current | D8: 0012 1000 7225 | E8: LKR | F8: -12733558 | G8: 1.5288718e+08 | H8: -33636116 | I8: 1.065175e+08 | J8: 0 | K8: =+I8+13500000 -> 1.200175e+08 | L8: * With POD 13.5Mn
A9: Citrus Leisure PLC | B9: Seylan | C9: Current | D9: 0860 1358 9928 001 | E9: LKR | F9: 93500 | G9: 0 | H9: -2000 | I9: 91500 | J9: 0 | K9: =+I9 -> 91500
A10: Citrus Leisure PLC | B10: Commercial | C10: Current | D10: 1000 8947 43 | E10: LKR | F10: 3704954.3 | G10: 11500000 | H10: -9261636.6 | I10: 5943317.7 | J10: 0 | K10: =+I10 -> 5943317.7
A11: Citrus Leisure PLC | B11: Peoples - RI | C11: Current | D11: 148 1001 0005 0085 | E11: LKR | F11: 0 | G11: 0 | H11: 0 | I11: 0 | K11: 0
A12: Citrus Leisure PLC | B12: Peoples | C12: Current | D12: 1361 001 034 18931 | E12: LKR | F12: 40847.09 | G12: 0 | H12: 0 | I12: 40847.09 | J12: =+I12 -> 40847.09 | K12: 0
A14: Waskaduwa Beach Resort PLC | B14: Sampath | C14: Current | D14: 002930022406 | E14: LKR | F14: -50253101 | G14: 19302504 | H14: -7533328.1 | I14: -38483925 | J14: 0 | K14: =50000000+I14 -> 11516075 | L14: * With POD 50Mn
A15: Waskaduwa Beach Resort PLC | B15: Sampath | C15: Current | D15: 002930025324 | E15: LKR | F15: 18772472 | G15: 1754726.2 | H15: -18550500 | I15: 1976698.5 | J15: 0 | K15: =+I15 -> 1976698.5
A16: Waskaduwa Beach Resort PLC | B16: Sampath | C16: Current | D16: 502909000268 | E16: USD | F16: =8.42*319.34 -> 2688.8428 | G16: =2812.7*319.34 -> 898207.62 | H16: 0 | I16: =2821.12*319.34 -> 900896.46 | J16: 0 | K16: =+I16 -> 900896.46 | L16: * USD Rate 319.34
A17: Waskaduwa Beach Resort PLC | B17: Commercial | C17: Current | D17: 1030018169 | E17: LKR | F17: 4197213.7 | G17: 2160220.9 | H17: -6267826.1 | I17: 89608.5 | J17: 0 | K17: =+I17 -> 89608.5
A18: Waskaduwa Beach Resort PLC | B18: Commercial | C18: Current | D18: 1000911976 | E18: LKR | F18: 4845741.9 | G18: 30000000 | H18: -26822613 | I18: 8023128.7 | J18: 0 | K18: =+I18 -> 8023128.7
A19: Waskaduwa Beach Resort PLC | B19: PABC | C19: Current | D19: 100111001078 | E19: LKR | F19: 406158.75 | G19: 0 | H19: -250 | I19: 405908.75 | J19: =+I19 -> 405908.75 | K19: 0
A20: Waskaduwa Beach Resort PLC | B20: Peoples | C20: Current | D20: 309100180008189 | E20: LKR | F20: 112918.7 | G20: 0 | H20: 0 | I20: 112918.7 | J20: =+I20 -> 112918.7 | K20: 0
A21: Waskaduwa Beach Resort PLC | B21: Seylan | C21: Current | D21: 086013589957001 | E21: LKR | F21: 82500 | G21: 0 | H21: -2000 | I21: 80500 | J21: 0 | K21: =+I21 -> 80500
A23: Hikkaduwa Beach Resort PLC | B23: Sampath | C23: Current | D23: 2930021019 | E23: LKR | F23: -20903508 | G23: 73023525 | H23: -75531498 | I23: -23411481 | J23: 0 | K23: =+I23+25000000 -> 1588518.8 | L23: * With POD 25Mn
A24: Hikkaduwa Beach Resort PLC | B24: Sampath | C24: Current | D24: 2930021205 | E24: LKR | F24: 1444179.8 | G24: 38872460 | H24: -39150497 | I24: 1166143.1 | J24: 0 | K24: =+I24 -> 1166143.1
A25: Hikkaduwa Beach Resort PLC | B25: Sampath | C25: Current | D25: 11810000270 | E25: LKR | F25: 43982.95 | G25: 8032312.5 | H25: -7000750 | I25: 1075545.4 | J25: 0 | K25: =+I25 -> 1075545.4
A26: Hikkaduwa Beach Resort PLC | B26: Sampath | C26: Current | D26: 502909000241 | E26: GBP | F26: =1490*430.41 -> 641310.9 | G26: 0 | H26: 0 | I26: =1490*430.41 -> 641310.9 | J26: =650*430.41 -> 279766.5 | K26: =+I26-J26 -> 361544.4 | L26: * GBP Rate 430.41
A27: Hikkaduwa Beach Resort PLC | B27: Sampath | C27: Current | D27: 502930001451 | E27: USD | F27: =2202.75*319.34 -> 703426.18 | G27: =140.74*319.34 -> 44943.912 | H27: =+-2200*319.34 -> -702548 | I27: =143.49*319.34 -> 45822.097 | J27: 0 | K27: =+I27 -> 45822.097 | L27: * USD Rate 319.34
A28: Hikkaduwa Beach Resort PLC | B28: Sampath | C28: Current | D28: 502930097884 | E28: EUR | F28: =4840.53*372.68 -> 1803968.7 | G28: =15235.06*372.68 -> 5677802.2 | H28: =+-17820*372.68 -> -6641157.6 | I28: =2255.59*372.68 -> 840613.28 | J28: 0 | K28: =+I28 -> 840613.28 | L28: * EUR Rate 372.68
A29: Hikkaduwa Beach Resort PLC | B29: Commercial | C29: Current | D29: 1140033233 | E29: LKR | F29: 188267.5 | G29: 5600000 | H29: -5400950 | I29: 387317.5 | J29: 0 | K29: =+I29 -> 387317.5
A30: Hikkaduwa Beach Resort PLC | B30: Commercial | C30: Current | D30: 1000914779 | E30: LKR | F30: 1111071.6 | G30: 19900000 | H30: -17530441 | I30: 3480630.4 | J30: 0 | K30: =+I30 -> 3480630.4
A31: Hikkaduwa Beach Resort PLC | B31: Peoples | C31: Current | D31: 136100140032845 | E31: LKR | F31: 316622.87 | G31: 0 | H31: 0 | I31: 316622.87 | J31: =+I31 -> 316622.87 | K31: 0
A32: Hikkaduwa Beach Resort PLC | B32: NDB Wealth | C32: Money Market A/C | D32: 1023274-01 | E32: LKR | F32: 208371.21 | G32: 1329.81 | H32: 0 | I32: 209701.01 | J32: 0 | K32: =+I32 -> 209701.01
A33: Hikkaduwa Beach Resort PLC | B33: PABC | C33: Current | D33: 100166000978 | E33: LKR | F33: 182659.82 | G33: 18000000 | H33: -18021547 | I33: 161112.53 | J33: 0 | K33: =+I33 -> 161112.53
A34: Hikkaduwa Beach Resort PLC | B34: PABC | C34: Current | D34: 100111000880 | E34: LKR | F34: 42000 | G34: 0 | H34: -250 | I34: 41750 | J34: =+I34 -> 41750 | K34: 0
A35: Hikkaduwa Beach Resort PLC | B35: NTB | C35: Current | D35: 100870009540 | E35: LKR | F35: 1831817.2 | G35: 807108.32 | H35: -1801100 | I35: 837825.55 | J35: 0 | K35: =+I35 -> 837825.55
A36: Hikkaduwa Beach Resort PLC | B36: Seylan | C36: Current | D36: 86013589944001 | E36: LKR | F36: 94500 | G36: 0 | H36: -2000 | I36: 92500 | J36: 0 | K36: =+I36 -> 92500
A38: Citrus Silver Limited | B38: Sampath | C38: Current | D38: 002930027831 | E38: LKR | F38: -12429323 | G38: 30000 | H38: -84114.45 | I38: -12483438 | J38: 0 | K38: =+I38+12500000 -> 16562.35 | L38: * With POD 12.5Mn
A39: Citrus Silver Limited | B39: Sampath | C39: Current | D39: 002930027858 | E39: LKR | F39: 2344385.7 | G39: 14624877 | H39: -14322831 | I39: 2646432.5 | J39: 0 | K39: =+I39 -> 2646432.5
A40: Citrus Silver Limited | B40: Commercial | C40: Current | D40: 1000923818 | E40: LKR | F40: 1544202.1 | G40: 14913750 | H40: -11000657 | I40: 5457295.3 | K40: =+I40 -> 5457295.3
A41: Citrus Silver Limited | B41: HNB | C41: Current | D41: 081010011965 | E41: LKR | F41: -54091558 | G41: 33716587 | H41: -35506965 | I41: -55881937 | J41: 0 | K41: =+I41+57000000 -> 1118063.5 | L41: * With POD 57Mn
A42: Citrus Silver Limited | B42: HNB | C42: Current | D42: 202010003330 | E42: LKR | F42: 22061.57 | G42: 0 | H42: -950 | I42: 21111.57 | J42: 0 | K42: =+I42 -> 21111.57
A43: Citrus Silver Limited | B43: HNB | C43: Current | D43: 081010015734 | E43: LKR | F43: 27581.36 | G43: 0 | H43: -1050 | I43: 26531.36 | J43: 0 | K43: =+I43 -> 26531.36
A44: Citrus Silver Limited | B44: HNB | C44: Current | D44: 202010003349 | E44: USD | F44: =1712.99*319.34 -> 547026.23 | G44: =435*319.34 -> 138912.9 | H44: =-1652*319.34 -> -527549.68 | I44: =495.99*319.34 -> 158389.45 | J44: 0 | K44: =+I44 -> 158389.45 | L44: * USD Rate 319.34
...

Sheet 3. Citrus Group
A3: 3. GS Group loan _ deposit portfolio
A5: 3.1 Long Term Loan
A6: Company | B6: Bank | C6: Loan type | D6: Tenor | E6: Facility amount | F6: Initially granted / Restructured date | G6: Current Interest rate | H6: Remaining Tenor | I6: Outstanding amount as at 30 Apr 2026 | K6: Restructured Amount
A8: Waskaduwa Beach Resort PLC | B8: Sampath | C8: Term Loan | D8: 96 Months | E8: 844400000 | F8: 45863 | G8: AWPLR + 1% | H8: 87 Months | I8: 776260000 | K8: 798660000
C9: Term Loan | D9: 96 Months | E9: 540500000 | F9: 45863 | G9: AWPLR + 1% | H9: 87 Months | I9: 494650000 | K9: 510050000
C10: Moratorium Loan | D10: 40 Months | E10: 533000000 | F10: 45863 | G10: 0.08 | H10: 31 Months | I10: 324110000 | K10: 338110000
C11: Term Loan | D11: 94 Months | E11: 100000000 | F11: 45925 | G11: AWPLR + 1% | H11: 87 Months | I11: 97600000 | K11: 0
C12: Term Loan | D12: 96 Months | E12: 63500000 | F12: 45863 | G12: AWPLR + 1% | H12: 87 Months | I12: 62100000 | K12: 0
A14: Hikkaduwa Beach Resort PLC | B14: Sampath | C14: Term Loan | D14: 95 Months | E14: 210400000 | F14: 45894 | G14: AWPLR + 1% | H14: 87 Months | I14: 178600000 | K14: 189100000
C15: Term Loan | D15: 95 Months | E15: 140000000 | F15: 45894 | G15: AWPLR + 1% | H15: 87 Months | I15: 123100000 | K15: 130000000
C16: Moratorium Loan | D16: 35 Months | E16: 95000000 | F16: 45894 | G16: 0.08 | H16: 27 Months | I16: 65030000 | K16: 74630000
C17: Term Loan | D17: 94 Months | E17: 100000000 | F17: 45925 | G17: AWPLR + 1% | H17: 87 Months | I17: 97600000 | K17: 0
B18: PABC | C18: Short Term Loan | D18: 60 Months | E18: 837150000 | F18: 45413 | G18: AWPLR + 1.5% | H18: 37 Months | I18: 4.8380098e+08 | K18: 7.1381095e+08
C19: Short Term Loan | D19: 60 Months | E19: 169000000 | F19: 45413 | G19: 0.06 | H19: 37 Months | I19: 87867499 | K19: 1.3461431e+08
A21: Citrus Silver Limited | B21: HNB | C21: Term Loan | D21: 37 Months | E21: 77000000 | F21: 45475 | G21: AWPLR + 2% | H21: 16 Months | I21: 14446469 | K21: 34811905
C22: Short Term Revolving Loan | D22: 4 Months | E22: 40000000 | F22: 46079 | G22: AWPLR + 2% | H22: On Demand | I22: 40000000 | K22: 0
A24: 3.2 Working Capital loan
A25: Company | B25: Bank | C25: Facility type | D25: Tenor | E25: Facility amount Rs./FCY | F25: Rate | G25: Outstanding amount as at 30 Apr 2026 Rs./FCY
A26: Waskaduwa Beach Resort PLC | B26: Sampath | C26: POD | D26: On Demand | E26: 50000000 | F26: AWPLR + 1% | G26: 38483925
A27: Hikkaduwa Beach Resort PLC | B27: Sampath | C27: POD | D27: On Demand | E27: 25000000 | F27: AWPLR + 1% | G27: 23411481
A28: Citrus Leisure PLC | B28: Sampath | C28: POD | D28: On Demand | E28: 13500000 | F28: AWPLR + 1% | G28: 0
A29: Citrus Silver Limited | B29: Sampath | C29: POD | D29: On Demand | E29: 12500000 | F29: AWPLR + 1% | G29: 12483438
B30: HNB | C30: POD | D30: On Demand | E30: 57000000 | F30: AWPLR + 2% | G30: 55881937
A32: 3.3 Fixed Deposit/Other Deposits
A33: Company | B33: Bank/Institute | C33: Amount Rs./FCY | D33: Commencement date | E33: Maturity date | F33: Tenor | G33: Rate | H33: Pledged details (if any)
A34: Citrus Leisure PLC | B34: Sampath | C34: 22622705 | D34: 46138 | E34: 46229 | F34: 3 months | G34: 0.07 | H34: POD
A35: Citrus Silver Limited | B35: Sampath | C35: 11228461 | D35: 46090 | E35: 46182 | F35: 3 months | G35: 0.07 | H35: POD
C36: 9007267.7 | D36: 46096 | E36: 46188 | F36: 3 months | G36: 0.07 | H36: POD

Sheet 1 & 3 GSIB
A1: 1. Daily Group Cash Position Report -
A2: Purpose: Immediate visibility of available liquidity
A4: Entity | B4: Bank | C4: Account type | D4: Account # | E4: Currency | F4: Opening Balance - May | G4: Inflows | H4: Outflows | I4: Closing Balance | J4: Restricted Cash | K4: Available Cash - Apr | L4: USD closing Balance
A5: George Steuart Insurance Brokers (Pvt) Ltd | B5: Cargills | C5: Current | D5: 1950000702 | E5: LKR | F5: 4724573.4 | I5: =F5+G5-H5 -> 4724573.4 | J5: 9000000 | K5: =I5 -> 4724573.4 | M5: 46142
A6: George Steuart Insurance Brokers (Pvt) Ltd | B6: Cargills | C6: Higher Saving | D6: 0011 0700 6091 | E6: LKR | F6: 4684573.4 | I6: =F6+G6-H6 -> 4684573.4 | K6: =I6 -> 4684573.4 | M6: 46142
A7: George Steuart Insurance Brokers (Pvt) Ltd | B7: Cargills | C7: Saving | D7: 1103000201 | E7: LKR | F7: 15284.1 | I7: =F7+G7-H7 -> 15284.1 | K7: =I7 -> 15284.1
A8: George Steuart Insurance Brokers (Pvt) Ltd | B8: Cargills | C8: Saving | D8: 0011 0700 9604 | E8: LKR | F8: 154926.2 | G8: 0 | H8: 0 | I8: =F8 -> 154926.2 | K8: =I8 -> 154926.2
A9: George Steuart Insurance Brokers (Pvt) Ltd | B9: NDB | C9: Saving | D9: 106590006893 | E9: USD | F9: 3761241 | H9: 0 | I9: =F9+G9-H9 -> 3761241 | K9: =I9 -> 3761241 | L9: 11897.65
A10: George Steuart Insurance Brokers (Pvt) Ltd | B10: NDB | C10: Current | D10: 101001103866 | E10: LKR | F10: 739788.97 | G10: 0 | I10: =F10+G10-H10 -> 739788.97 | K10: =I10 -> 739788.97
A11: George Steuart Insurance Brokers (Pvt) Ltd | B11: BOC | C11: Saving | D11: 91834522 | E11: LKR | F11: 10586.67 | I11: =F11+G11-H11 -> 10586.67 | K11: =I11 -> 10586.67
A12: George Steuart Insurance Brokers (Pvt) Ltd | B12: BOC | C12: Current | D12: 91834503 | E12: LKR | F12: 331174.85 | G12: 19850000 | H12: 19859292 | I12: =F12+G12-H12 -> 321882.4 | K12: =I12 -> 321882.4
A13: George Steuart Insurance Brokers (Pvt) Ltd | B13: Sampath | C13: Saving | D13: 5034 2000 3627 | E13: USD | F13: 5794859.4 | H13: 0 | I13: =F13+G13-H13 -> 5794859.4 | K13: =I13 -> 5794859.4 | L13: 18322.8
A14: George Steuart Insurance Brokers (Pvt) Ltd | B14: Sampath | C14: Current | D14: 0034 1001 2218 | E14: LKR | F14: 26263 | G14: 0 | H14: 50 | I14: =F14+G14-H14 -> 26213 | K14: =I14 -> 26213
A15: George Steuart Insurance Brokers (Pvt) Ltd | B15: Seylan | C15: Current | D15: 0860 12728996 001 | E15: LKR | F15: -10974123 | G15: 0 | H15: 569473.79 | I15: =F15+G15-H15 -> -11543597 | K15: =I15 -> -11543597
A16: George Steuart Insurance Brokers (Pvt) Ltd | B16: Seylan | C16: Current | D16: 0860 12728996 002 | E16: LKR | F16: 25000 | G16: 0 | H16: 0 | I16: =F16+G16-H16 -> 25000 | K16: =I16 -> 25000
A17: George Steuart Insurance Brokers (Pvt) Ltd | B17: Seylan | C17: Saving | D17: 0860 12728996 066 | E17: USD | F17: 54132701 | I17: =F17+G17-H17 -> 54132701 | K17: =I17 -> 54132701 | L17: 171376.52
A18: George Steuart Insurance Brokers (Pvt) Ltd | B18: Seylan | C18: Money Market | D18: 0860 12728996 123 | E18: LKR | F18: 427148.98 | G18: 11427416 | H18: 2801991.1 | I18: =F18+G18-H18 -> 9052574.2 | K18: =I18 -> 9052574.2
A19: George Steuart Insurance Brokers (Pvt) Ltd | B19: Union | C19: Saving | D19: 0120 2010 0005 6523 | E19: LKR | F19: 225162.66 | G19: 369.8 | H19: 786.98 | I19: =F19+G19-H19 -> 224745.48 | K19: =I19 -> 224745.48
A20: George Steuart Insurance Brokers (Pvt) Ltd | B20: Union | C20: Current | D20: 0120 1010 0001 6836 | E20: LKR | F20: 80386.84 | I20: =F20+G20-H20 -> 80386.84 | K20: =I20 -> 80386.84
A21: George Steuart Insurance Brokers (Pvt) Ltd | B21: Commercial | C21: Current | D21: 1680025087 | E21: LKR | F21: 6505.38 | G21: 0 | I21: =F21+G21-H21 -> 6505.38 | K21: =I21 -> 6505.38
A22: George Steuart Insurance Brokers (Pvt) Ltd | B22: Commercial | C22: Current | D22: (1)-1020012908 | E22: LKR | F22: 22980224 | H22: 0 | I22: =F22+G22-H22 -> 22980224 | K22: =I22 -> 22980224
A24: 2. Rolling 13-Week Cash Flow Forecast (Core Treasury Tool)
A25: Purpose: Short-term liquidity planning – 03 months
B26: (a) | C26: (b) | D26: (c) | E26: (b-c)=d | F26: (e) | G26: (f) | H26: (g) | I26: (d-e-f-g)=h | J26: (a+h)
A27: Week | B27: Opening Cash | C27: Operating Inflows | D27: Operating Outflows | E27: Net Operating | F27: Capex | G27: Debt Service | H27: Other | I27: Net Cash Flow | J27: Closing Cash
A28: W1
A35: 3. GS Group loan _ deposit portfolio
A37: 3.1 Long Term Loan
A38: Company | B38: Bank | C38: Loan type | D38: Tenor | E38: Facility amount | F38: Initially granted date | G38: Current Interest rate | H38: Remaining Tenor | I38: Outstanding amount as at 31 Jan 2026
A41: 3.2 Working Capital loan
A42: Company | B42: Bank | C42: Facility type | D42: Tenor | E42: Facility amount Rs./FCY | F42: Rate | G42: Outstanding amount as at 31 Jan 2026 Rs./FCY
A45: 3.3 Fixed Deposit/Other Deposits
A46: Company | B46: Bank/Institute | C46: Amount Rs./FCY | D46: Commencement date | E46: Maturity date | F46: Tenor | G46: Rate | H46: Pledged details (if any)
A47: George Steuart Insurance Brokers (Pvt) Ltd | B47: NDB Wealth | C47: 2569647.9 | D47: 19.09.2024 | E47: 28.02.2026 | F47: One Month | G47: 0.0751 | H47: No
A48: George Steuart Insurance Brokers (Pvt) Ltd | B48: Cargills Bank | C48: 5815546.1 | D48: 21.11.2023 | E48: 20.02.2026 | F48: 03 Months | G48: 0.075 | H48: No
A49: George Steuart Insurance Brokers (Pvt) Ltd | B49: Cargills Bank | C49: 331129.45 | D49: 16.05.2024 | E49: 15.02.2026 | F49: 03 Months | G49: 0.075 | H49: No
A50: George Steuart Insurance Brokers (Pvt) Ltd | B50: Cargills Bank | C50: 330659.33 | D50: 09.04.2024 | E50: 08.04.2026 | F50: 03 Months | G50: 0.07 | H50: No
A51: George Steuart Insurance Brokers (Pvt) Ltd | B51: Cargills Bank | C51: 675096.14 | D51: 14.03.2024 | E51: 13.03.2026 | F51: 03 Months | G51: 0.075 | H51: No
A52: George Steuart Insurance Brokers (Pvt) Ltd | B52: Seylan Bank (LKR) | C52: 932324.62 | D52: 24.05.2017 | E52: 23.02.2026 | F52: One Month | G52: 0.06 | H52: No
A53: George Steuart Insurance Brokers (Pvt) Ltd | B53: Seylan Bank (USD) | C53: 1.208895e+08 | D53: 13.10.2025 | E53: 11.04.2026 | F53: 06 Months | G53: 0.0525 | H53: No
...

Sheet 1. GSH
A1: 1. Daily Group Cash Position Report -
A2: Purpose: Immediate visibility of available liquidity
A4: Entity | B4: Bank | C4: Account type | D4: Account # | E4: Currency | F4: Opening Balance - March | G4: Inflows | H4: Outflows | I4: Closing Balance | J4: Restricted Cash | K4: Available Cash - March
A5: GSH | B5: NDB | C5: Current | D5: 1010 0002 5071 | E5: LKR | F5: -1.1685668e+08 | G5: 40928826 | H5: 46451946 | I5: =F5+G5-H5 -> -1.223798e+08 | J5: 0 | K5: =I5-J5 -> -1.223798e+08
B6: NDB | C6: Saving | D6: 1065-9000-6001 | E6: USD | F6: 44607219 | G6: 0 | H6: 0 | I6: =F6+G6-H6 -> 44607219 | J6: 0 | K6: =I6-J6 -> 44607219
B7: DFCC | C7: Current | D7: 102072013996 | E7: USD | F7: -26328.68 | G7: 0 | H7: 0 | I7: =F7+G7-H7 -> -26328.68 | J7: 0 | K7: =I7-J7 -> -26328.68
B8: DFCC | C8: Current | D8: 101014573128 | E8: LKR | F8: 6837856.4 | G8: 2.8878088e+08 | H8: 3091310.1 | I8: =F8+G8-H8 -> 2.9252742e+08 | J8: 0 | K8: =I8-J8 -> 2.9252742e+08
B9: Seylan | C9: Current | D9: 0080-13334985-001 | E9: LKR | F9: 1313300.5 | G9: 277307.1 | H9: 12000 | I9: =F9+G9-H9 -> 1578607.6 | J9: 0 | K9: =I9-J9 -> 1578607.6
B10: Seylan | C10: Current | D10: 0860-13334985002 | E10: LKR | F10: -87440627 | G10: 0 | H10: 0 | I10: =F10+G10-H10 -> -87440627 | J10: 0 | K10: =I10-J10 -> -87440627
B11: Sampath | C11: Current | D11: 0091-1000-7245 | E11: LKR | F11: 2346372.5 | G11: 434605 | H11: 20248000 | I11: =F11+G11-H11 -> -17467022 | J11: 0 | K11: =I11-J11 -> -17467022
B12: Sampath | C12: Current | D12: 0009- 3000 -0027 | E12: LKR | F12: 8538813.6 | G12: 70504091 | H12: 0 | I12: =F12+G12-H12 -> 79042905 | J12: 0 | K12: =I12-J12 -> 79042905
B13: Sampath | C13: Current | D13: 0018 1000 4351 | E13: LKR | F13: -1036531.8 | G13: 434605 | H13: 20248000 | I13: =F13+G13-H13 -> -20849927 | K13: =I13-J13 -> -20849927
B14: HNB | C14: Current | D14: 61010277822 | E14: LKR | F14: 2173016 | G14: 4425475 | H14: 50000000 | I14: =F14+G14-H14 -> -43401509 | J14: 0 | K14: =I14-J14 -> -43401509
B15: HNB | C15: Current | D15: 0020 1000 3748 | E15: LKR | F15: 2168806.2 | G15: 766287.82 | H15: 0 | I15: =F15+G15-H15 -> 2935094 | J15: 0 | K15: =I15-J15 -> 2935094
B16: Peoples | C16: Current | D16: 4100191976807 | E16: LKR | F16: 2068821.3 | G16: 0 | H16: 0 | I16: =F16+G16-H16 -> 2068821.3 | J16: 0 | K16: =I16-J16 -> 2068821.3
B17: BOC | C17: Current | D17: 70848912 | E17: LKR | F17: 3.0816101e+08 | G17: 49794782 | H17: 60011925 | I17: =F17+G17-H17 -> 2.9794386e+08 | J17: 0 | K17: =I17-J17 -> 2.9794386e+08
B18: Comm Bank | C18: Current | D18: 2020045110 | E18: LKR | F18: 25000 | G18: 0 | H18: 0 | I18: =F18+G18-H18 -> 25000 | J18: 0 | K18: =I18-J18 -> 25000
B19: Comm Bank | C19: MMS | D19: 1020012905 | E19: LKR | F19: 25115780 | G19: 0 | H19: 0 | I19: =F19+G19-H19 -> 25115780 | J19: 0 | K19: =I19-J19 -> 25115780

Sheet 3. GSH
A1: GS Group Loan / deposit Portfolio
A4: Long Term Loan
A5: Company | B5: Bank | C5: Loan type | D5: Tenor | E5: Facility amount | F5: Initially granted date | G5: Current Interest rate | H5: Remaining Tenor (Months) | I5: Outstanding amount as at 08th May 2026
A6: GSH | B6: BOC | C6: Capex funding | D6: 48 Months | E6: 125000000 | F6: 45444 | G6: 0.0994 | H6: 25 | I6: 67800000
A7: GSH | B7: Seylan | C7: Vehicle | D7: 36 Months | E7: 90000000 | F7: 45627 | G7: 0.1 | H7: =ROUND(I7/J7,0) -> 19 | I7: 47500000 | J7: 2500000
A8: GSH | B8: Seylan | C8: Capex funding | D8: 84 months - 06 months | E8: 200000000 | F8: 45281 | G8: 0.1 | H8: =ROUND(I8/J8,0) -> 56 | I8: 143570000 | J8: 2565000
A9: GSH | B9: Seylan | C9: Capex funding | D9: 84 Months with 03 months Grace Period | E9: 400000000 | F9: 45391 | G9: 0.1 | H9: =ROUND(I9/J9,0) -> 60 | I9: 305380000 | J9: 5090000
A12: Working Capital loan
A13: Company | B13: Bank | C13: Facility type | D13: Tenor | E13: Facility amount Rs./FCY | F13: Rate | G13: Outstanding amount as at 08th May 2026
A14: GSH | B14: HNB | C14: Money Market Loan | D14: 3 Months Revolving | E14: 120000000 | F14: 0.098 | G14: =E14 -> 120000000
A15: GSH | B15: HNB | C15: Money Market Loan | D15: 3 Months Revolving | E15: 130000000 | F15: 0.098 | G15: =E15 -> 130000000
A18: Fixed Deposit/Other Deposits
A19: Company | B19: Bank/Institute | C19: Amount Rs./FCY | D19: Maturity date | E19: Tenor | F19: Rate | G19: Pledged details (if any)
A20: GSH | B20: NDB | C20: 20,594,942.53 | D20: 8th Nov 2025 | E20: 6 Months | F20: 0.09
A21: GSH | B21: NDB | C21: 58,344,435.83 | D21: 9th May 2026 | E21: 3 Months | F21: 0.0835
A22: GSH | B22: NDB | C22: 10,189,428.30 | D22: 11th July 2026 | E22: 3 Months | F22: 0.075
A23: GSH | B23: NDB | C23: 16,747,949.66 | D23: 19th May 2026 | E23: 3 Months | F23: 0.0835
A24: GSH | B24: DFCC | C24: 15,323,509.93 | D24: 9th Aug 2026 | E24: 6 Months | F24: 0.0825
A25: GSH | B25: DFCC | C25: 14,704,193.84 | D25: 8th June 2026 | E25: 6 Months | F25: 0.07 | G25: Pledged to OD
A26: GSH | B26: DFCC | C26: 35,407,351.49 | D26: 24th May 2026 | E26: 3 Months | F26: 0.0825 | G26: Pledged to OD
A27: GSH | B27: DFCC | C27: 300,000,000.00 | D27: 04th June 2026 | E27: 3 Months | F27: 0.091 | G27: Pledged to OD
A28: GSH | B28: HNB | C28: 12,095,136.01 | D28: 6th Aug 2025 | E28: 3 Months | F28: 0.085 | G28: Pledged to OD
A29: GSH | B29: HNB | C29: 14,003,122.15 | D29: 21st June 2026 | E29: 3 Months | F29: 0.085 | G29: Pledged to OD
A30: GSH | B30: HNB | C30: 15,919,664.30 | D30: 30th June 2026 | E30: 3 Months | F30: 0.085 | G30: Pledged to OD
A31: GSH | B31: HNB | C31: 17,568,360.37 | D31: 1st Sep 2026 | E31: 6 Months | F31: 0.085 | G31: Pledged to OD
A32: GSH | B32: BOC | C32: 3,114,431.27 | D32: 8th July 2026 | E32: 3 Months | F32: 0.0625
A33: GSH | B33: NDB Wealth | C33: 30,158,687.59 | D33: - | E33: N/A | F33: -

Sheet 1 & 3 GST
A1: 1. Daily Group Cash Position Report -
A2: Purpose: Immediate visibility of available liquidity
A4: Entity | B4: Bank | C4: Account type | D4: Account # | E4: Currency | F4: Bank Balance as at 30/04/2026 | G4: Bank Balance as at 31/03/2026
A7: George Steuart Teas (Pvt) Ltd | B7: BOC | C7: C/A | D7: 7230989 | E7: LKR | F7: 9295103.2 | G7: 10327677
B8: BOC | C8: BFCA | D8: 7231039 | E8: USD | F8: 296800.45 | G8: 30987.7
B9: BOC | C9: BLA | D9: 88359063 | E9: USD | F9: 639.74 | G9: 639.74
B10: BOC | C10: BFCA | D10: 71799300 | E10: EURO | F10: 211.55 | G10: 9363.5854
B11: Peoples | C11: C/A | D11: 148100130046167 | E11: LKR | F11: 99999950 | G11: -1050
B12: Peoples | C12: BFCA | D12: 148402130046167 | E12: USD | F12: 962.95 | G12: 6992.16
B13: Peoples | C13: BLA | D13: 148402220046167 | E13: USD
B14: Peoples Lian
B15: Seylan | C15: C/A | D15: 86013585844001 | E15: LKR | F15: 291661.12 | G15: 27531075
B16: Seylan | C16: BFCA | D16: 86013585844050 | E16: USD | F16: 17445.43 | G16: 681.8
B17: Seylan | C17: BLA | D17: 86013585844001 | E17: USD | F17: 266.1 | G17: 811.1
B18: HNB | C18: C/A | D18: 2010015083 | E18: LKR | F18: -297154.88 | G18: 17421363
B19: HNB | C19: C/A | D19: 2010016836 | E19: LKR | F19: 6181731.7 | G19: 7312546.1
B20: HNB | C20: BFCA | D20: 2910138541 | E20: USD | F20: 90616.91 | G20: 129495.62
B21: HNB | C21: BLA | D21: 2910469986 | E21: USD | F21: 864.51 | G21: 864.51
B22: NDB | C22: C/A | D22: 101000017672 | E22: LKR | F22: 35696465 | G22: 34624541
B23: NDB | C23: BFCA | D23: 101570000145 | E23: USD | F23: 818.74 | G23: 8149.18
B24: NDB | C24: BLA | D24: 106840000748 | E24: USD | F24: 417.84 | G24: 417.49
B25: China Bank | C25: C/A | D25: 100002800009382 | E25: LKR
B26: China Bank | C26: BFCA | D26: 100002800009406 | E26: USD
B27: China Bank | C27: BFCA | D27: 100002800009393 | E27: EURO
A31: 2. Rolling 13-Week Cash Flow Forecast (Core Treasury Tool)
A32: Purpose: Short-term liquidity planning – 03 months
B33: (a) | C33: (b) | D33: (c) | E33: (b-c)=d | F33: (e) | G33: (f) | H33: (g) | I33: (d-e-f-g)=h | J33: (a+h)
A34: Week | B34: Opening Cash | C34: Operating Inflows | D34: Operating Outflows | E34: Net Operating | F34: Capex | G34: Debt Service | H34: Other | I34: Net Cash Flow | J34: Closing Cash
A35: W1
A36: W2
A42: 3. GS Group loan _ deposit portfolio
A44: 3.1 Long Term Loan | I44: 46112
A45: Company | B45: Bank | C45: Loan type | D45: Tenor | E45: Facility amount | F45: Initially granted date | G45: Current Interest rate | H45: Remaining Tenor | I45: Outstanding amount as at 31 March 2026 | N45: Maturity date
A46: George Steuart Teas (Pvt) Ltd | B46: BOC | C46: Term Loan | D46: 10 Y | E46: 843566410 | F46: 44340 | G46: 0.0996 | H46: =IF($I$44>=N46,"0",DATEDIF($I$44,N46,"Y") & " Years " & DATEDIF($I$44,N46,"YM") & " Months") -> 5 Years 1 Months | I46: 5.4252473e+08 | N46: =EDATE(F46, 10*12) -> 47992
B47: BOC | C47: Term Loan | D47: 10 Y | E47: 400000000 | F47: 45433 | G47: 0.0991 | H47: =IF($I$44>=N47,"0",DATEDIF($I$44,N47,"Y") & " Years " & DATEDIF($I$44,N47,"YM") & " Months") -> 8 Years 1 Months | I47: 326520000 | N47: =EDATE(F47, 10*12) -> 49085
B48: HNB | C48: Term Loan | D48: 5 Y | E48: 90000000 | F48: 45275 | G48: 0.1094 | H48: =IF($I$44>=N48,"0",DATEDIF($I$44,N48,"Y") & " Years " & DATEDIF($I$44,N48,"YM") & " Months") -> 2 Years 8 Months | I48: 49500000 | N48: =EDATE(F48, 5*12) -> 47102
B49: HNB | C49: Term Loan | D49: 5 Y | E49: 88000000 | F49: 45607 | G49: 0.1069 | H49: =IF($I$44>=N49,"0",DATEDIF($I$44,N49,"Y") & " Years " & DATEDIF($I$44,N49,"YM") & " Months") -> 3 Years 7 Months | I49: 64533333 | N49: =EDATE(F49, 5*12) -> 47433
B50: HNB | C50: Term Loan | D50: 5 Y | E50: 100000000 | F50: 45798 | G50: 0.0974 | H50: =IF($I$44>=N50,"0",DATEDIF($I$44,N50,"Y") & " Years " & DATEDIF($I$44,N50,"YM") & " Months") -> 4 Years 1 Months | I50: 83333333 | N50: =EDATE(F50, 5*12) -> 47624
B51: HNB | C51: Term Loan | D51: 5 Y | E51: 90000000 | F51: 45947 | G51: 0.0974 | H51: =IF($I$44>=N51,"0",DATEDIF($I$44,N51,"Y") & " Years " & DATEDIF($I$44,N51,"YM") & " Months") -> 4 Years 6 Months | I51: 82500000 | N51: =EDATE(F51, 5*12) -> 47773
B52: PB | C52: Term Loan | D52: 3 Y | E52: 50000000 | F52: 45068 | G52: 0.1683 | H52: =IF($I$44>=N52,"0",DATEDIF($I$44,N52,"Y") & " Years " & DATEDIF($I$44,N52,"YM") & " Months") -> 0 Years 1 Months | I52: 2777778.1 | N52: =EDATE(F52, 3*12) -> 46164
...

Sheet 1 & 3 GS Ticketing
A1: 1. Daily Group Cash Position Report -
A2: Purpose: Immediate visibility of available liquidity
A4: Entity | B4: Bank | C4: Account type | D4: Account # | E4: Currency | F4: Opening Balance - 22/04/2026 | G4: Inflows | H4: Outflows | I4: Closing Balance - 04/05/2026 | J4: Restricted Cash | K4: Available Cash - 04/05/2026 | M4: Interbank Fund Transfers
A5: George Steuart Travels Ltd | B5: BOC | C5: C/A | D5: 71068290 | E5: LKR | F5: -1593742.9 | G5: 425500 | H5: -356613.94 | I5: =SUM(F5:H5) -> -1524856.9 | J5: 0 | K5: 175155.04 | L5: * | M5: NDB | N5: Inflow | O5: Outflow
A6: George Steuart Travels Ltd | B6: NDB * | C6: C/A | D6: 101000234638 | E6: LKR | F6: -1.3767456e+08 | G6: =37000000+106874398.47 -> 1.438744e+08 | H6: =-41203176.99-95071548-1094544.62-7578904.5 -> -1.4494817e+08 | I6: =SUM(F6:H6) -> -1.3874833e+08 | J6: 0 | K6: -1.3275793e+08 | M6: Peoples | N6: =-H10-100 -> 3791000
A7: George Steuart Travels Ltd | B7: Sampath ** | C7: C/A | D7: 000930000574 | E7: LKR | F7: 1748408.9 | G7: 5891563.5 | H7: -6395628.9 | I7: =SUM(F7:H7) -> 1244343.5 | J7: 0 | K7: 2948453.9 | M7: NTB | N7: =-H11-100 -> 3475000
A8: George Steuart Travels Ltd | B8: Sampath | C8: C/A | D8: 000911000523 | E8: LKR | F8: 3505 | G8: 0 | H8: -600 | I8: =SUM(F8:H8) -> 2905 | J8: 0 | K8: =+I8 -> 2905 | M8: Commercial
A9: George Steuart Travels Ltd | B9: Union | C9: C/A | D9: 9970101000004250 | E9: LKR | F9: 157250.97 | G9: 0 | H9: -157251 | I9: =SUM(F9:H9) -> -0.03 | J9: 0 | K9: =+I9 -> -0.03
A10: George Steuart Travels Ltd | B10: Peoples | C10: C/A | D10: 148100110050706 | E10: LKR | F10: -14624.31 | G10: 6324427.9 | H10: -3791100 | I10: =SUM(F10:H10) -> 2518703.6 | J10: 0 | K10: 2576850.4
A11: George Steuart Travels Ltd | B11: NTB | C11: C/A | D11: 100020013810 | E11: LKR | F11: 648113.97 | G11: 7908145 | H11: -3475100 | I11: =SUM(F11:H11) -> 5081159 | J11: 0 | K11: 5077690.4 | L11: ** | M11: Sampath | N11: Inflow | O11: Outflow
A12: George Steuart Travels Ltd | B12: Comm Bank | C12: C/A | D12: 1020012896 | E12: LKR | F12: 2191875.2 | G12: 0 | H12: 0 | I12: =SUM(F12:H12) -> 2191875.2 | J12: 0 | K12: =+I12 -> 2191875.2 | M12: SB-Islamic
A13: George Steuart Travels Ltd | B13: NDB | C13: S/A | D13: 106630000249 | E13: USD | F13: 7388.86 | G13: 0 | H13: 0 | I13: =SUM(F13:H13) -> 7388.86 | J13: 0 | K13: =+I13 -> 7388.86
A14: George Steuart Travels Ltd | B14: Sampath | C14: S/A | D14: 500930004122 | E14: USD | F14: 15012.5 | G14: 0 | H14: 0 | I14: =SUM(F14:H14) -> 15012.5 | J14: 0 | K14: =+I14 -> 15012.5
A17: 2. Rolling 13-Week Cash Flow Forecast (Core Treasury Tool)
A18: Purpose: Short-term liquidity planning – 03 months
B19: (a) | C19: (b) | D19: (c) | E19: (b-c)=d | F19: (e) | G19: (f) | H19: (g) | I19: (d-e-f-g)=h | J19: (a+h)
A20: Week | B20: Opening Cash | C20: Operating Inflows | D20: Operating Outflows | E20: Net Operating | F20: Capex | G20: Debt Service | H20: Other | I20: Net Cash Flow | J20: Closing Cash
A21: W1 | B21: Pending
A28: 3. GS Group loan _ deposit portfolio
A30: 3.1 Long Term Loan
A31: Company | B31: Bank | C31: Loan type | D31: Tenor | E31: Facility amount | F31: Initially granted date | G31: Current Interest rate | H31: Remaining Tenor | I31: Outstanding amount as at 04/05/2026
A32: George Steuart Travels Ltd | B32: NDB | C32: Moratorium Loan | D32: 5 Years | E32: 100000000 | F32: 44110 | G32: 0.17 | H32: 5 | I32: 7076732.4
A33: George Steuart Travels Ltd | B33: Union | C33: Vehicle Loan | D33: 5 Years | E33: 20000000 | F33: 20/05/2025 | G33: 0.1115 | H33: 49 | I33: 17064876
A36: 3.2 Working Capital loan
A37: Company | B37: Bank | C37: Facility type | D37: Tenor | E37: Facility amount Rs./FCY | F37: Rate | G37: Outstanding amount as at 04/05/2026 Rs./FCY
A38: George Steuart Travels Ltd | B38: NDB | C38: Short Term Loan | D38: 45Days | E38: 160000000 | F38: AWPLR+1% | G38: =+[1]Annexure1!C14 -> 3.5835463e+08 | H38: Annexure1
A39: George Steuart Travels Ltd | B39: NDB | C39: Overdraft | D39: On Demand | E39: 100000000 | F39: AWPLR+1% | G39: -1.3275793e+08
A40: George Steuart Travels Ltd | B40: Sampath | C40: Corporate Credit Card | D40: 25Days | E40: 1750000 | F40: 0.26 | G40: =+E40-24617.54 -> 1725382.5 | H40: 46142
A41: George Steuart Travels Ltd | B41: Cargills | C41: Corporate Credit Card | D41: 25Days | E41: 4500000 | F41: 0.26 | G41: =+E41-63762.87 -> 4436237.1 | H41: 46143
A44: 3.3 Fixed Deposit/Other Deposits
A45: Company | B45: Bank/Institute | C45: Amount Rs./FCY | D45: Commencement date | E45: Maturity date | F45: Tenor | G45: Rate | H45: Pledged details (if any) | I45: Update 04/05/2026
A46: George Steuart Travels Ltd | B46: NDB | C46: 11990959 | D46: 15/08/2025 | E46: 15/08/2026 | F46: 1Years | G46: 0.0725 | H46: Lien over the above-mentioned NDB facilities and IATA Bank Guarantee
A47: George Steuart Travels Ltd | B47: NDB | C47: 9874437.1 | D47: 26/01/2026 | E47: 26/01/2027 | F47: 1Years | G47: 0.0825
A48: George Steuart Travels Ltd | B48: NDB | C48: 3097793.5 | D48: 45758 | E48: 46123 | F48: 1Years | G48: 0.08
A49: George Steuart Travels Ltd | B49: NDB | C49: 20000000 | D49: 02/02/2026 | E49: 02/02/2027 | F49: 1Years | G49: 0.085
A50: George Steuart Travels Ltd | B50: NDB - Big Saver | C50: 3321941 | D50: Up to the facility withdrawal date | G50: 0.04
A51: George Steuart Travels Ltd | B51: SB - CD | C51: 872693.76 | E51: - | F51: - | G51: 0.025 | H51: -
A52: George Steuart Travels Ltd | B52: Cargills | C52: 1468887.5 | D52: 26/04/2022 | E52: 19/05/2026 | F52: 1Years | G52: 0.086 | H52: - | I52: Lien removed but FD uplift is only after maturity
A53: George Steuart Travels Ltd | B53: Cargills | C53: 2176254.3 | D53: 30/05/2022 | E53: 46270 | F53: 1Years | G53: 0.086 | H53: -
A54: George Steuart Travels Ltd | B54: Cargills | C54: 2851577.2 | D54: 29/07/2022 | E54: 46120 | F54: 1Years | G54: 0.0825 | H54: -

Sheet 3. GSTravels Annexure1
A1: 114490261527 | B1: AA260229LN4Y | C1: 20000000 | D1: 22/01/2026 | E1: 0.12
A2: 114490264103 | B2: AA260305HHPP | C2: 45000000 | D2: 30/01/2026 | E2: 0.0976
A3: 114490272057 | B3: AA26063GPWWJ | C3: 7054626.8 | D3: 46084 | E3: 0.0978
A4: 114490273463 | B4: AA26068YCLPB | C4: 10000000 | D4: 46268 | E4: 0.1036
A5: 114490275393 | B5: AA260758QHTC | C5: 85000000 | D5: 16/03/2026 | E5: 0.11
A6: 114490276691 | B6: AA26079FJ9MF | C6: 24000000 | D6: 20/03/2026 | E6: 0.12
A7: 114490277345 | B7: AA26082H426W | C7: 16000000 | D7: 23/03/2026 | E7: 0.11
A8: 114490279248 | B8: AA26089YPPDH | C8: 21000000 | D8: 30/03/2026 | E8: 0.0978
A9: 114490280966 | B9: AA26097DY4HP | C9: 60000000 | D9: 46207 | E9: 0.12
A10: 114490282489 | B10: AA26105SCC50 | C10: 33300000 | D10: 15/04/2026 | E10: 0.12
A11: 114490283817 | B11: AA26112W3BGJ | C11: 22000000 | D11: 22/04/2026 | E11: 0.12
A12: 114490286018 | B12: AA26120T9BMF | C12: 15000000 | D12: 30/04/2026 | E12: 0.12
C14: =SUM(C1:C13) -> 3.5835463e+08
A17: 22/04/2026 | C17: 3.7068317e+08
